Workbook

Sheet Read Me
A1: Weekly Service Level Performance Narrative Template
A2: Built for Lou to share with Bindu and Jay. Includes criteria, formulas, example, action tracker, and narrative template.
A4: How to use | B4: Instructions
A5: 1 | B5: Update the Data Input sheet with the prior week interval/day data. Blue cells are intended for manual input.
A6: 2 | B6: Review the Example Weekly Narrative sheet. It shows one clear worked example using sample data.
A7: 3 | B7: Use the Criteria Matrix to align on what should be reported weekly and who owns each item.
A8: 4 | B8: Use the Action Tracker to document follow-up items and keep owners/due dates explicit.
A9: 5 | B9: Use the Narrative Template sheet to copy into the weekly note to Rimi.

Sheet Criteria Matrix
A1: Weekly Service Level Performance Criteria Matrix
A2: Criteria aligned to Rimi ask plus recommended best-practice additions using first principles and Pareto.
A5: Category | B5: Report Item | C5: Definition / Question Answered | D5: Calculation / Formula | E5: Threshold / Flag | F5: Owner | G5: Cadence | H5: Why It Matters
A6: Core SLA | B6: Total intervals missed 2-min AWT target | C6: How many intervals exceeded the 2-minute average wait time target? | D6: COUNTIF(interval AWT, ">2:00") | E6: Any miss = review; severe miss >5:00 | F6: WFM | G6: Weekly | H6: Direct answer to Rimi ask and top indicator of customer wait experience.
A7: Core SLA | B7: Days with missed intervals | C7: How many days had one or more missed intervals? | D7: COUNTUNIQUE(day where missed intervals >0) | E7: More days = broader systemic issue | F7: WFM | G7: Weekly | H7: Separates isolated bad interval from multi-day pattern.
A8: Core SLA | B8: Miss severity bands | C8: Were misses minor, moderate, or severe? | D8: Minor 2:01-3:00; Moderate 3:01-5:00; Severe >5:00 | E8: Severe >0 = leadership visibility | F8: WFM | G8: Weekly | H8: Not all misses carry the same customer impact.
A9: Core SLA | B9: Miss concentration by day/time block | C9: Where were misses clustered? | D9: Pivot missed intervals by day and time block | E9: Top day/time block should get priority | F9: WFM | G9: Weekly | H9: Supports Pareto analysis by focusing action on highest concentration.
A10: Customer Experience | B10: Abandonment exception >7% | C10: Which days exceeded the 7% abandon threshold? | D10: Abandoned calls / Offered calls | E10: >7.0% = exception | F10: WFM | G10: Weekly | H10: Rimi specifically requested visibility on any day above 7%.
A11: Customer Experience | B11: Short vs true abandons | C11: Are abandonments customer experience-related or immediate hangups? | D11: Gross abandon vs abandon after threshold if available | E11: Use available system definition | F11: WFM | G11: Weekly | H11: Improves data quality and avoids overreacting to immediate hangups.
A12: Demand | B12: Forecast accuracy | C12: Was demand higher/lower than forecast? | D12: (Actual calls - Forecast calls) / Forecast calls | E12: >+/-10% = review | F12: WFM | G12: Weekly | H12: Determines if miss began with demand planning.
A13: Supply | B13: Required vs scheduled vs productive staff | C13: Did scheduled coverage become productive coverage? | D13: Required staff vs scheduled staff vs actual productive staff | E13: Productive gap drives SLA risk | F13: WFM | G13: Weekly | H13: Shows if capacity was planned, scheduled, and actually available.
A14: Availability | B14: Shrinkage / lost hours | C14: Did absence, tardy, coaching, meetings, or aux reduce capacity? | D14: Lost hours / scheduled hours | E14: Above plan = root cause review | F14: WFM + Site Ops | G14: Weekly | H14: Explains why a staffed site still misses SLA.
A15: Availability | B15: Adherence / conformance diagnostic | C15: Did agents follow schedule? | D15: Actual in-adherence time / scheduled time | E15: Diagnostic only; avoid punitive gate | F15: WFM + Site Ops | G15: Weekly | H15: Helps explain interval misses without incentivizing gaming.
A16: Productivity | B16: AHT variance | C16: Did handle time exceed plan and build queues? | D16: Actual AHT - target AHT | E16: Above plan during miss intervals = review | F16: Care Ops + QA | G16: Weekly | H16: Links operational process/knowledge gaps to SLA misses.
... A20: Leadership Action | B20: Immediate action items | C20: What needs to happen next week? | D20: Owner + due date + expected impact | E20: Every repeat driver must have action | F20: Lou / WFM / Ops | G20: Weekly | H20: Creates accountability and closes the loop.

Sheet Data Input
A1: Data Input - Weekly WFM Fields
A2: Blue input cells should be updated by WFM each week. Formulas support the weekly narrative.
A5: Week Start | B5: Week End | C5: Day | D5: Time Block | E5: Forecast Calls | F5: Offered Calls | G5: Handled Calls | H5: Abandoned Calls | I5: Abandon % | J5: Abn>30s Calls | K5: Abn>30s % | L5: AWT Minutes | M5: AHT Seconds | N5: Required Staff | O5: Scheduled Staff | P5: Productive Staff | Q5: Primary Driver | R5: Action Taken | S5: Miss Rank (Helper - Do Not Edit)
A6: 46236 | B6: =DataInput[[#This Row],[Week Start]]+6 -> 46242 | C6: Monday | D6: 0.33333333 | E6: 140 | F6: 139 | G6: 131 | H6: 8 | I6: 0.057553957 | J6: 6 | K6: 0.043165468 | L6: 1.3400763 | M6: 364.07353 | N6: 41 | O6: 54.335 | P6: 51.779444 | S6: =IF(L6>2,COUNTIF($L$6:L6,">2"),"")
A7: 46236 | B7: =DataInput[[#This Row],[Week Start]]+6 -> 46242 | C7: Monday | D7: 0.35416667 | E7: 217 | F7: 227 | G7: 197 | H7: 30 | I7: 0.13215859 | J7: 25 | K7: 0.11013216 | L7: 3.3928088 | M7: 436.50754 | N7: 68 | O7: 58.665 | P7: 59.212222 | S7: =IF(L7>2,COUNTIF($L$6:L7,">2"),"") -> 1
A8: 46236 | B8: =DataInput[[#This Row],[Week Start]]+6 -> 46242 | C8: Monday | D8: 0.375 | E8: 218 | F8: 234 | G8: 223 | H8: 11 | I8: 0.047008547 | J8: 6 | K8: 0.025641026 | L8: 1.7 | M8: 469.34934 | N8: 74 | O8: 80.835 | P8: 80.206111 | S8: =IF(L8>2,COUNTIF($L$6:L8,">2"),"")
A9: 46236 | B9: =DataInput[[#This Row],[Week Start]]+6 -> 46242 | C9: Monday | D9: 0.39583333 | E9: 235 | F9: 247 | G9: 245 | H9: 2 | I9: 0.008097166 | J9: 0 | K9: 0 | L9: 0.12952381 | M9: 416.94862 | N9: 70 | O9: 86.17 | P9: 88.231111 | S9: =IF(L9>2,COUNTIF($L$6:L9,">2"),"")
A10: 46236 | B10: =DataInput[[#This Row],[Week Start]]+6 -> 46242 | C10: Monday | D10: 0.41666667 | E10: 288 | F10: 318 | G10: 294 | H10: 24 | I10: 0.075471698 | J10: 19 | K10: 0.059748428 | L10: 0.65136054 | M10: 425.24 | N10: 85.5 | O10: 89.335 | P10: 87.074444 | S10: =IF(L10>2,COUNTIF($L$6:L10,">2"),"")
A11: 46236 | B11: =DataInput[[#This Row],[Week Start]]+6 -> 46242 | C11: Monday | D11: 0.4375 | E11: 323 | F11: 370 | G11: 316 | H11: 54 | I11: 0.14594595 | J11: 47 | K11: 0.12702703 | L11: 3.0749473 | M11: 445.54321 | N11: 92 | O11: 77.5 | P11: 76.568889 | S11: =IF(L11>2,COUNTIF($L$6:L11,">2"),"") -> 2
A12: 46236 | B12: =DataInput[[#This Row],[Week Start]]+6 -> 46242 | C12: Monday | D12: 0.45833333 | E12: 319 | F12: 341 | G12: 309 | H12: 32 | I12: 0.093841642 | J12: 26 | K12: 0.076246334 | L12: 3.7696872 | M12: 459.55205 | N12: 92.5 | O12: 87 | P12: 80.240556 | S12: =IF(L12>2,COUNTIF($L$6:L12,">2"),"") -> 3
A13: 46236 | B13: =DataInput[[#This Row],[Week Start]]+6 -> 46242 | C13: Monday | D13: 0.47916667 | E13: 313 | F13: 328 | G13: 313 | H13: 15 | I13: 0.045731707 | J13: 5 | K13: 0.015243902 | L13: 1.3446219 | M13: 455.21562 | N13: 95 | O13: 81 | P13: 83.838333 | S13: =IF(L13>2,COUNTIF($L$6:L13,">2"),"")
A14: 46236 | B14: =DataInput[[#This Row],[Week Start]]+6 -> 46242 | C14: Monday | D14: 0.5 | E14: 314 | F14: 349 | G14: 317 | H14: 32 | I14: 0.091690544 | J14: 27 | K14: 0.077363897 | L14: 2.0086225 | M14: 425.78614 | N14: 91 | O14: 73 | P14: 77.671667 | S14: =IF(L14>2,COUNTIF($L$6:L14,">2"),"") -> 4
A15: 46236 | B15: =DataInput[[#This Row],[Week Start]]+6 -> 46242 | C15: Monday | D15: 0.52083333 | E15: 291 | F15: 315 | G15: 281 | H15: 34 | I15: 0.10793651 | J15: 28 | K15: 0.088888889 | L15: 2.347153 | M15: 446.85324 | N15: 100.5 | O15: 78 | P15: 72.795 | S15: =IF(L15>2,COUNTIF($L$6:L15,">2"),"") -> 5
A16: 46236 | B16: =DataInput[[#This Row],[Week Start]]+6 -> 46242 | C16: Monday | D16: 0.54166667 | E16: 282 | F16: 275 | G16: 244 | H16: 31 | I16: 0.11272727 | J16: 23 | K16: 0.083636364 | L16: 2.2172131 | M16: 484.01594 | N16: 91 | O16: 81 | P16: 74.867778 | S16: =IF(L16>2,COUNTIF($L$6:L16,">2"),"") -> 6
A17: 46236 | B17: =DataInput[[#This Row],[Week Start]]+6 -> 46242 | C17: Monday | D17: 0.5625 | E17: 309 | F17: 344 | G17: 301 | H17: 43 | I17: 0.125 | J17: 33 | K17: 0.095930233 | L17: 3.1544297 | M17: 492.66559 | N17: 97 | O17: 83.165 | P17: 79.711667 | S17: =IF(L17>2,COUNTIF($L$6:L17,">2"),"") -> 7
... A143: 46236 | B143: =DataInput[[#This Row],[Week Start]]+6 -> 46242 | C143: Saturday | D143: 0.75 | E143: 15 | F143: 26 | G143: 26 | H143: 0 | I143: 0 | J143: 0 | K143: 0 | L143: 0.11346154 | M143: 519.48148 | N143: 10 | O143: 1 | P143: 4.5588889 | S143: =IF(L143>2,COUNTIF($L$6:L143,">2"),"")

Sheet Missed AWT Intervals
A1: Missed AWT Interval Report
A2: Auto-updates from the Data Input tab. Every interval where AWT Minutes exceeded the 2:00 target is listed below - no manual copying needed.
A3: Total Missed Intervals This Week: | B3: =COUNTIF('Data Input'!L6:L143,">2") -> 53 | D3: Severe Misses (>5:00): | E3: =COUNTIF('Data Input'!L6:L143,">5") -> 20
A5: # | B5: Day | C5: Time Block | D5: AWT Minutes | E5: Severity | F5: Offered Calls | G5: Abandoned Calls | H5: Abandon % | I5: AHT Seconds | J5: Primary Driver | K5: Action Taken
A6: =IF(1<=$B$3,1,"") -> 1 | B6: =IF($A6="","",INDEX('Data Input'!$C$6:$C$143,MATCH($A6,'Data Input'!$S$6:$S$143,0))) -> Monday | C6: =IF($A6="","",INDEX('Data Input'!$D$6:$D$143,MATCH($A6,'Data Input'!$S$6:$S$143,0))) -> 0.35416667 | D6: =IF($A6="","",INDEX('Data Input'!$L$6:$L$143,MATCH($A6,'Data Input'!$S$6:$S$143,0))) -> 3.3928088 | E6: =IF($A6="","",IF(D6>5,"Severe",IF(D6>3,"Moderate","Minor"))) -> Moderate | F6: =IF($A6="","",INDEX('Data Input'!$F$6:$F$143,MATCH($A6,'Data Input'!$S$6:$S$143,0))) -> 227 | G6: =IF($A6="","",INDEX('Data Input'!$H$6:$H$143,MATCH($A6,'Data Input'!$S$6:$S$143,0))) -> 30 | H6: =IF($A6="","",INDEX('Data Input'!$I$6:$I$143,MATCH($A6,'Data Input'!$S$6:$S$143,0))) -> 0.13215859 | I6: =IF($A6="","",INDEX('Data Input'!$M$6:$M$143,MATCH($A6,'Data Input'!$S$6:$S$143,0))) -> 436.50754 | J6: =IF($A6="","",IFERROR(IF(INDEX('Data Input'!$Q$6:$Q$143,MATCH($A6,'Data Input'!$S$6:$S$143,0))="","",INDEX('Data Input'!$Q$6:$Q$143,MATCH($A6,'Data Input'!$S$6:$S$143,0))),"")) | K6: =IF($A6="","",IFERROR(IF(INDEX('Data Input'!$R$6:$R$143,MATCH($A6,'Data Input'!$S$6:$S$143,0))="","",INDEX('Data Input'!$R$6:$R$143,MATCH($A6,'Data Input'!$S$6:$S$143,0))),""))
A7: =IF(2<=$B$3,2,"") -> 2 | B7: =IF($A7="","",INDEX('Data Input'!$C$6:$C$143,MATCH($A7,'Data Input'!$S$6:$S$143,0))) -> Monday | C7: =IF($A7="","",INDEX('Data Input'!$D$6:$D$143,MATCH($A7,'Data Input'!$S$6:$S$143,0))) -> 0.4375 | D7: =IF($A7="","",INDEX('Data Input'!$L$6:$L$143,MATCH($A7,'Data Input'!$S$6:$S$143,0))) -> 3.0749473 | E7: =IF($A7="","",IF(D7>5,"Severe",IF(D7>3,"Moderate","Minor"))) -> Moderate | F7: =IF($A7="","",INDEX('Data Input'!$F$6:$F$143,MATCH($A7,'Data Input'!$S$6:$S$143,0))) -> 370 | G7: =IF($A7="","",INDEX('Data Input'!$H$6:$H$143,MATCH($A7,'Data Input'!$S$6:$S$143,0))) -> 54 | H7: =IF($A7="","",INDEX('Data Input'!$I$6:$I$143,MATCH($A7,'Data Input'!$S$6:$S$143,0))) -> 0.14594595 | I7: =IF($A7="","",INDEX('Data Input'!$M$6:$M$143,MATCH($A7,'Data Input'!$S$6:$S$143,0))) -> 445.54321 | J7: =IF($A7="","",IFERROR(IF(INDEX('Data Input'!$Q$6:$Q$143,MATCH($A7,'Data Input'!$S$6:$S$143,0))="","",INDEX('Data Input'!$Q$6:$Q$143,MATCH($A7,'Data Input'!$S$6:$S$143,0))),"")) | K7: =IF($A7="","",IFERROR(IF(INDEX('Data Input'!$R$6:$R$143,MATCH($A7,'Data Input'!$S$6:$S$143,0))="","",INDEX('Data Input'!$R$6:$R$143,MATCH($A7,'Data Input'!$S$6:$S$143,0))),""))
A8: =IF(3<=$B$3,3,"") -> 3 | B8: =IF($A8="","",INDEX('Data Input'!$C$6:$C$143,MATCH($A8,'Data Input'!$S$6:$S$143,0))) -> Monday | C8: =IF($A8="","",INDEX('Data Input'!$D$6:$D$143,MATCH($A8,'Data Input'!$S$6:$S$143,0))) -> 0.45833333 | D8: =IF($A8="","",INDEX('Data Input'!$L$6:$L$143,MATCH($A8,'Data Input'!$S$6:$S$143,0))) -> 3.7696872 | E8: =IF($A8="","",IF(D8>5,"Severe",IF(D8>3,"Moderate","Minor"))) -> Moderate | F8: =IF($A8="","",INDEX('Data Input'!$F$6:$F$143,MATCH($A8,'Data Input'!$S$6:$S$143,0))) -> 341 | G8: =IF($A8="","",INDEX('Data Input'!$H$6:$H$143,MATCH($A8,'Data Input'!$S$6:$S$143,0))) -> 32 | H8: =IF($A8="","",INDEX('Data Input'!$I$6:$I$143,MATCH($A8,'Data Input'!$S$6:$S$143,0))) -> 0.093841642 | I8: =IF($A8="","",INDEX('Data Input'!$M$6:$M$143,MATCH($A8,'Data Input'!$S$6:$S$143,0))) -> 459.55205 | J8: =IF($A8="","",IFERROR(IF(INDEX('Data Input'!$Q$6:$Q$143,MATCH($A8,'Data Input'!$S$6:$S$143,0))="","",INDEX('Data Input'!$Q$6:$Q$143,MATCH($A8,'Data Input'!$S$6:$S$143,0))),"")) | K8: =IF($A8="","",IFERROR(IF(INDEX('Data Input'!$R$6:$R$143,MATCH($A8,'Data Input'!$S$6:$S$143,0))="","",INDEX('Data Input'!$R$6:$R$143,MATCH($A8,'Data Input'!$S$6:$S$143,0))),""))
A9: =IF(4<=$B$3,4,"") -> 4 | B9: =IF($A9="","",INDEX('Data Input'!$C$6:$C$143,MATCH($A9,'Data Input'!$S$6:$S$143,0))) -> Monday | C9: =IF($A9="","",INDEX('Data Input'!$D$6:$D$143,MATCH($A9,'Data Input'!$S$6:$S$143,0))) -> 0.5 | D9: =IF($A9="","",INDEX('Data Input'!$L$6:$L$143,MATCH($A9,'Data Input'!$S$6:$S$143,0))) -> 2.0086225 | E9: =IF($A9="","",IF(D9>5,"Severe",IF(D9>3,"Moderate","Minor"))) -> Minor | F9: =IF($A9="","",INDEX('Data Input'!$F$6:$F$143,MATCH($A9,'Data Input'!$S$6:$S$143,0))) -> 349 | G9: =IF($A9="","",INDEX('Data Input'!$H$6:$H$143,MATCH($A9,'Data Input'!$S$6:$S$143,0))) -> 32 | H9: =IF($A9="","",INDEX('Data Input'!$I$6:$I$143,MATCH($A9,'Data Input'!$S$6:$S$143,0))) -> 0.091690544 | I9: =IF($A9="","",INDEX('Data Input'!$M$6:$M$143,MATCH($A9,'Data Input'!$S$6:$S$143,0))) -> 425.78614 | J9: =IF($A9="","",IFERROR(IF(INDEX('Data Input'!$Q$6:$Q$143,MATCH($A9,'Data Input'!$S$6:$S$143,0))="","",INDEX('Data Input'!$Q$6:$Q$143,MATCH($A9,'Data Input'!$S$6:$S$143,0))),"")) | K9: =IF($A9="","",IFERROR(IF(INDEX('Data Input'!$R$6:$R$143,MATCH($A9,'Data Input'!$S$6:$S$143,0))="","",INDEX('Data Input'!$R$6:$R$143,MATCH($A9,'Data Input'!$S$6:$S$143,0))),""))
A10: =IF(5<=$B$3,5,"") -> 5 | B10: =IF($A10="","",INDEX('Data Input'!$C$6:$C$143,MATCH($A10,'Data Input'!$S$6:$S$143,0))) -> Monday | C10: =IF($A10="","",INDEX('Data Input'!$D$6:$D$143,MATCH($A10,'Data Input'!$S$6:$S$143,0))) -> 0.52083333 | D10: =IF($A10="","",INDEX('Data Input'!$L$6:$L$143,MATCH($A10,'Data Input'!$S$6:$S$143,0))) -> 2.347153 | E10: =IF($A10="","",IF(D10>5,"Severe",IF(D10>3,"Moderate","Minor"))) -> Minor | F10: =IF($A10="","",INDEX('Data Input'!$F$6:$F$143,MATCH($A10,'Data Input'!$S$6:$S$143,0))) -> 315 | G10: =IF($A10="","",INDEX('Data Input'!$H$6:$H$143,MATCH($A10,'Data Input'!$S$6:$S$143,0))) -> 34 | H10: =IF($A10="","",INDEX('Data Input'!$I$6:$I$143,MATCH($A10,'Data Input'!$S$6:$S$143,0))) -> 0.10793651 | I10: =IF($A10="","",INDEX('Data Input'!$M$6:$M$143,MATCH($A10,'Data Input'!$S$6:$S$143,0))) -> 446.85324 | J10: =IF($A10="","",IFERROR(IF(INDEX('Data Input'!$Q$6:$Q$143,MATCH($A10,'Data Input'!$S$6:$S$143,0))="","",INDEX('Data Input'!$Q$6:$Q$143,MATCH($A10,'Data Input'!$S$6:$S$143,0))),"")) | K10: =IF($A10="","",IFERROR(IF(INDEX('Data Input'!$R$6:$R$143,MATCH($A10,'Data Input'!$S$6:$S$143,0))="","",INDEX('Data Input'!$R$6:$R$143,MATCH($A10,'Data Input'!$S$6:$S$143,0))),""))
A11: =IF(6<=$B$3,6,"") -> 6 | B11: =IF($A11="","",INDEX('Data Input'!$C$6:$C$143,MATCH($A11,'Data Input'!$S$6:$S$143,0))) -> Monday | C11: =IF($A11="","",INDEX('Data Input'!$D$6:$D$143,MATCH($A11,'Data Input'!$S$6:$S$143,0))) -> 0.54166667 | D11: =IF($A11="","",INDEX('Data Input'!$L$6:$L$143,MATCH($A11,'Data Input'!$S$6:$S$143,0))) -> 2.2172131 | E11: =IF($A11="","",IF(D11>5,"Severe",IF(D11>3,"Moderate","Minor"))) -> Minor | F11: =IF($A11="","",INDEX('Data Input'!$F$6:$F$143,MATCH($A11,'Data Input'!$S$6:$S$143,0))) -> 275 | G11: =IF($A11="","",INDEX('Data Input'!$H$6:$H$143,MATCH($A11,'Data Input'!$S$6:$S$143,0))) -> 31 | H11: =IF($A11="","",INDEX('Data Input'!$I$6:$I$143,MATCH($A11,'Data Input'!$S$6:$S$143,0))) -> 0.11272727 | I11: =IF($A11="","",INDEX('Data Input'!$M$6:$M$143,MATCH($A11,'Data Input'!$S$6:$S$143,0))) -> 484.01594 | J11: =IF($A11="","",IFERROR(IF(INDEX('Data Input'!$Q$6:$Q$143,MATCH($A11,'Data Input'!$S$6:$S$143,0))="","",INDEX('Data Input'!$Q$6:$Q$143,MATCH($A11,'Data Input'!$S$6:$S$143,0))),"")) | K11: =IF($A11="","",IFERROR(IF(INDEX('Data Input'!$R$6:$R$143,MATCH($A11,'Data Input'!$S$6:$S$143,0))="","",INDEX('Data Input'!$R$6:$R$143,MATCH($A11,'Data Input'!$S$6:$S$143,0))),""))
A12: =IF(7<=$B$3,7,"") -> 7 | B12: =IF($A12="","",INDEX('Data Input'!$C$6:$C$143,MATCH($A12,'Data Input'!$S$6:$S$143,0))) -> Monday | C12: =IF($A12="","",INDEX('Data Input'!$D$6:$D$143,MATCH($A12,'Data Input'!$S$6:$S$143,0))) -> 0.5625 | D12: =IF($A12="","",INDEX('Data Input'!$L$6:$L$143,MATCH($A12,'Data Input'!$S$6:$S$143,0))) -> 3.1544297 | E12: =IF($A12="","",IF(D12>5,"Severe",IF(D12>3,"Moderate","Minor"))) -> Moderate | F12: =IF($A12="","",INDEX('Data Input'!$F$6:$F$143,MATCH($A12,'Data Input'!$S$6:$S$143,0))) -> 344 | G12: =IF($A12="","",INDEX('Data Input'!$H$6:$H$143,MATCH($A12,'Data Input'!$S$6:$S$143,0))) -> 43 | H12: =IF($A12="","",INDEX('Data Input'!$I$6:$I$143,MATCH($A12,'Data Input'!$S$6:$S$143,0))) -> 0.125 | I12: =IF($A12="","",INDEX('Data Input'!$M$6:$M$143,MATCH($A12,'Data Input'!$S$6:$S$143,0))) -> 492.66559 | J12: =IF($A12="","",IFERROR(IF(INDEX('Data Input'!$Q$6:$Q$143,MATCH($A12,'Data Input'!$S$6:$S$143,0))="","",INDEX('Data Input'!$Q$6:$Q$143,MATCH($A12,'Data Input'!$S$6:$S$143,0))),"")) | K12: =IF($A12="","",IFERROR(IF(INDEX('Data Input'!$R$6:$R$143,MATCH($A12,'Data Input'!$S$6:$S$143,0))="","",INDEX('Data Input'!$R$6:$R$143,MATCH($A12,'Data Input'!$S$6:$S$143,0))),""))
A13: =IF(8<=$B$3,8,"") -> 8 | B13: =IF($A13="","",INDEX('Data Input'!$C$6:$C$143,MATCH($A13,'Data Input'!$S$6:$S$143,0))) -> Monday | C13: =IF($A13="","",INDEX('Data Input'!$D$6:$D$143,MATCH($A13,'Data Input'!$S$6:$S$143,0))) -> 0.58333333 | D13: =IF($A13="","",INDEX('Data Input'!$L$6:$L$143,MATCH($A13,'Data Input'!$S$6:$S$143,0))) -> 2.0238267 | E13: =IF($A13="","",IF(D13>5,"Severe",IF(D13>3,"Moderate","Minor"))) -> Minor | F13: =IF($A13="","",INDEX('Data Input'!$F$6:$F$143,MATCH($A13,'Data Input'!$S$6:$S$143,0))) -> 294 | G13: =IF($A13="","",INDEX('Data Input'!$H$6:$H$143,MATCH($A13,'Data Input'!$S$6:$S$143,0))) -> 17 | H13: =IF($A13="","",INDEX('Data Input'!$I$6:$I$143,MATCH($A13,'Data Input'!$S$6:$S$143,0))) -> 0.057823129 | I13: =IF($A13="","",INDEX('Data Input'!$M$6:$M$143,MATCH($A13,'Data Input'!$S$6:$S$143,0))) -> 465.37102 | J13: =IF($A13="","",IFERROR(IF(INDEX('Data Input'!$Q$6:$Q$143,MATCH($A13,'Data Input'!$S$6:$S$143,0))="","",INDEX('Data Input'!$Q$6:$Q$143,MATCH($A13,'Data Input'!$S$6:$S$143,0))),"")) | K13: =IF($A13="","",IFERROR(IF(INDEX('Data Input'!$R$6:$R$143,MATCH($A13,'Data Input'!$S$6:$S$143,0))="","",INDEX('Data Input'!$R$6:$R$143,MATCH($A13,'Data Input'!$S$6:$S$143,0))),""))
A14: =IF(9<=$B$3,9,"") -> 9 | B14: =IF($A14="","",INDEX('Data Input'!$C$6:$C$143,MATCH($A14,'Data Input'!$S$6:$S$143,0))) -> Monday | C14: =IF($A14="","",INDEX('Data Input'!$D$6:$D$143,MATCH($A14,'Data Input'!$S$6:$S$143,0))) -> 0.625 | D14: =IF($A14="","",INDEX('Data Input'!$L$6:$L$143,MATCH($A14,'Data Input'!$S$6:$S$143,0))) -> 4.2497792 | E14: =IF($A14="","",IF(D14>5,"Severe",IF(D14>3,"Moderate","Minor"))) -> Moderate | F14: =IF($A14="","",INDEX('Data Input'!$F$6:$F$143,MATCH($A14,'Data Input'!$S$6:$S$143,0))) -> 356 | G14: =IF($A14="","",INDEX('Data Input'!$H$6:$H$143,MATCH($A14,'Data Input'!$S$6:$S$143,0))) -> 54 | H14: =IF($A14="","",INDEX('Data Input'!$I$6:$I$143,MATCH($A14,'Data Input'!$S$6:$S$143,0))) -> 0.15168539 | I14: =IF($A14="","",INDEX('Data Input'!$M$6:$M$143,MATCH($A14,'Data Input'!$S$6:$S$143,0))) -> 493.44805 | J14: =IF($A14="","",IFERROR(IF(INDEX('Data Input'!$Q$6:$Q$143,MATCH($A14,'Data Input'!$S$6:$S$143,0))="","",INDEX('Data Input'!$Q$6:$Q$143,MATCH($A14,'Data Input'!$S$6:$S$143,0))),"")) | K14: =IF($A14="","",IFERROR(IF(INDEX('Data Input'!$R$6:$R$143,MATCH($A14,'Data Input'!$S$6:$S$143,0))="","",INDEX('Data Input'!$R$6:$R$143,MATCH($A14,'Data Input'!$S$6:$S$143,0))),""))
A15: =IF(10<=$B$3,10,"") -> 10 | B15: =IF($A15="","",INDEX('Data Input'!$C$6:$C$143,MATCH($A15,'Data Input'!$S$6:$S$143,0))) -> Monday | C15: =IF($A15="","",INDEX('Data Input'!$D$6:$D$143,MATCH($A15,'Data Input'!$S$6:$S$143,0))) -> 0.64583333 | D15: =IF($A15="","",INDEX('Data Input'!$L$6:$L$143,MATCH($A15,'Data Input'!$S$6:$S$143,0))) -> 4.2592915 | E15: =IF($A15="","",IF(D15>5,"Severe",IF(D15>3,"Moderate","Minor"))) -> Moderate | F15: =IF($A15="","",INDEX('Data Input'!$F$6:$F$143,MATCH($A15,'Data Input'!$S$6:$S$143,0))) -> 330 | G15: =IF($A15="","",INDEX('Data Input'!$H$6:$H$143,MATCH($A15,'Data Input'!$S$6:$S$143,0))) -> 43 | H15: =IF($A15="","",INDEX('Data Input'!$I$6:$I$143,MATCH($A15,'Data Input'!$S$6:$S$143,0))) -> 0.13030303 | I15: =IF($A15="","",INDEX('Data Input'!$M$6:$M$143,MATCH($A15,'Data Input'!$S$6:$S$143,0))) -> 463.02341 | J15: =IF($A15="","",IFERROR(IF(INDEX('Data Input'!$Q$6:$Q$143,MATCH($A15,'Data Input'!$S$6:$S$143,0))="","",INDEX('Data Input'!$Q$6:$Q$143,MATCH($A15,'Data Input'!$S$6:$S$143,0))),"")) | K15: =IF($A15="","",IFERROR(IF(INDEX('Data Input'!$R$6:$R$143,MATCH($A15,'Data Input'!$S$6:$S$143,0))="","",INDEX('Data Input'!$R$6:$R$143,MATCH($A15,'Data Input'!$S$6:$S$143,0))),""))
A16: =IF(11<=$B$3,11,"") -> 11 | B16: =IF($A16="","",INDEX('Data Input'!$C$6:$C$143,MATCH($A16,'Data Input'!$S$6:$S$143,0))) -> Monday | C16: =IF($A16="","",INDEX('Data Input'!$D$6:$D$143,MATCH($A16,'Data Input'!$S$6:$S$143,0))) -> 0.66666667 | D16: =IF($A16="","",INDEX('Data Input'!$L$6:$L$143,MATCH($A16,'Data Input'!$S$6:$S$143,0))) -> 2.9519608 | E16: =IF($A16="","",IF(D16>5,"Severe",IF(D16>3,"Moderate","Minor"))) -> Minor | F16: =IF($A16="","",INDEX('Data Input'!$F$6:$F$143,MATCH($A16,'Data Input'!$S$6:$S$143,0))) -> 380 | G16: =IF($A16="","",INDEX('Data Input'!$H$6:$H$143,MATCH($A16,'Data Input'!$S$6:$S$143,0))) -> 57 | H16: =IF($A16="","",INDEX('Data Input'!$I$6:$I$143,MATCH($A16,'Data Input'!$S$6:$S$143,0))) -> 0.15 | I16: =IF($A16="","",INDEX('Data Input'!$M$6:$M$143,MATCH($A16,'Data Input'!$S$6:$S$143,0))) -> 464.64048 | J16: =IF($A16="","",IFERROR(IF(INDEX('Data Input'!$Q$6:$Q$143,MATCH($A16,'Data Input'!$S$6:$S$143,0))="","",INDEX('Data Input'!$Q$6:$Q$143,MATCH($A16,'Data Input'!$S$6:$S$143,0))),"")) | K16: =IF($A16="","",IFERROR(IF(INDEX('Data Input'!$R$6:$R$143,MATCH($A16,'Data Input'!$S$6:$S$143,0))="","",INDEX('Data Input'!$R$6:$R$143,MATCH($A16,'Data Input'!$S$6:$S$143,0))),""))
A17: =IF(12<=$B$3,12,"") -> 12 | B17: =IF($A17="","",INDEX('Data Input'!$C$6:$C$143,MATCH($A17,'Data Input'!$S$6:$S$143,0))) -> Monday | C17: =IF($A17="","",INDEX('Data Input'!$D$6:$D$143,MATCH($A17,'Data Input'!$S$6:$S$143,0))) -> 0.6875 | D17: =IF($A17="","",INDEX('Data Input'!$L$6:$L$143,MATCH($A17,'Data Input'!$S$6:$S$143,0))) -> 2.3258602 | E17: =IF($A17="","",IF(D17>5,"Severe",IF(D17>3,"Moderate","Minor"))) -> Minor | F17: =IF($A17="","",INDEX('Data Input'!$F$6:$F$143,MATCH($A17,'Data Input'!$S$6:$S$143,0))) -> 332 | G17: =IF($A17="","",INDEX('Data Input'!$H$6:$H$143,MATCH($A17,'Data Input'!$S$6:$S$143,0))) -> 22 | H17: =IF($A17="","",INDEX('Data Input'!$I$6:$I$143,MATCH($A17,'Data Input'!$S$6:$S$143,0))) -> 0.06626506 | I17: =IF($A17="","",INDEX('Data Input'!$M$6:$M$143,MATCH($A17,'Data Input'!$S$6:$S$143,0))) -> 461.93375 | J17: =IF($A17="","",IFERROR(IF(INDEX('Data Input'!$Q$6:$Q$143,MATCH($A17,'Data Input'!$S$6:$S$143,0))="","",INDEX('Data Input'!$Q$6:$Q$143,MATCH($A17,'Data Input'!$S$6:$S$143,0))),"")) | K17: =IF($A17="","",IFERROR(IF(INDEX('Data Input'!$R$6:$R$143,MATCH($A17,'Data Input'!$S$6:$S$143,0))="","",INDEX('Data Input'!$R$6:$R$143,MATCH($A17,'Data Input'!$S$6:$S$143,0))),""))
A18: =IF(13<=$B$3,13,"") -> 13 | B18: =IF($A18="","",INDEX('Data Input'!$C$6:$C$143,MATCH($A18,'Data Input'!$S$6:$S$143,0))) -> Monday | C18: =IF($A18="","",INDEX('Data Input'!$D$6:$D$143,MATCH($A18,'Data Input'!$S$6:$S$143,0))) -> 0.75 | D18: =IF($A18="","",INDEX('Data Input'!$L$6:$L$143,MATCH($A18,'Data Input'!$S$6:$S$143,0))) -> 3.3009311 | E18: =IF($A18="","",IF(D18>5,"Severe",IF(D18>3,"Moderate","Minor"))) -> Moderate | F18: =IF($A18="","",INDEX('Data Input'!$F$6:$F$143,MATCH($A18,'Data Input'!$S$6:$S$143,0))) -> 232 | G18: =IF($A18="","",INDEX('Data Input'!$H$6:$H$143,MATCH($A18,'Data Input'!$S$6:$S$143,0))) -> 53 | H18: =IF($A18="","",INDEX('Data Input'!$I$6:$I$143,MATCH($A18,'Data Input'!$S$6:$S$143,0))) -> 0.22844828 | I18: =IF($A18="","",INDEX('Data Input'!$M$6:$M$143,MATCH($A18,'Data Input'!$S$6:$S$143,0))) -> 496.61749 | J18: =IF($A18="","",IFERROR(IF(INDEX('Data Input'!$Q$6:$Q$143,MATCH($A18,'Data Input'!$S$6:$S$143,0))="","",INDEX('Data Input'!$Q$6:$Q$143,MATCH($A18,'Data Input'!$S$6:$S$143,0))),"")) | K18: =IF($A18="","",IFERROR(IF(INDEX('Data Input'!$R$6:$R$143,MATCH($A18,'Data Input'!$S$6:$S$143,0))="","",INDEX('Data Input'!$R$6:$R$143,MATCH($A18,'Data Input'!$S$6:$S$143,0))),""))
A19: =IF(14<=$B$3,14,"") -> 14 | B19: =IF($A19="","",INDEX('Data Input'!$C$6:$C$143,MATCH($A19,'Data Input'!$S$6:$S$143,0))) -> Monday | C19: =IF($A19="","",INDEX('Data Input'!$D$6:$D$143,MATCH($A19,'Data Input'!$S$6:$S$143,0))) -> 0.77083333 | D19: =IF($A19="","",INDEX('Data Input'!$L$6:$L$143,MATCH($A19,'Data Input'!$S$6:$S$143,0))) -> 4.8477053 | E19: =IF($A19="","",IF(D19>5,"Severe",IF(D19>3,"Moderate","Minor"))) -> Moderate | F19: =IF($A19="","",INDEX('Data Input'!$F$6:$F$143,MATCH($A19,'Data Input'!$S$6:$S$143,0))) -> 172 | G19: =IF($A19="","",INDEX('Data Input'!$H$6:$H$143,MATCH($A19,'Data Input'!$S$6:$S$143,0))) -> 34 | H19: =IF($A19="","",INDEX('Data Input'!$I$6:$I$143,MATCH($A19,'Data Input'!$S$6:$S$143,0))) -> 0.19767442 | I19: =IF($A19="","",INDEX('Data Input'!$M$6:$M$143,MATCH($A19,'Data Input'!$S$6:$S$143,0))) -> 465.17808 | J19: =IF($A19="","",IFERROR(IF(INDEX('Data Input'!$Q$6:$Q$143,MATCH($A19,'Data Input'!$S$6:$S$143,0))="","",INDEX('Data Input'!$Q$6:$Q$143,MATCH($A19,'Data Input'!$S$6:$S$143,0))),"")) | K19: =IF($A19="","",IFERROR(IF(INDEX('Data Input'!$R$6:$R$143,MATCH($A19,'Data Input'!$S$6:$S$143,0))="","",INDEX('Data Input'!$R$6:$R$143,MATCH($A19,'Data Input'!$S$6:$S$143,0))),""))
A20: =IF(15<=$B$3,15,"") -> 15 | B20: =IF($A20="","",INDEX('Data Input'!$C$6:$C$143,MATCH($A20,'Data Input'!$S$6:$S$143,0))) -> Monday | C20: =IF($A20="","",INDEX('Data Input'!$D$6:$D$143,MATCH($A20,'Data Input'!$S$6:$S$143,0))) -> 0.79166667 | D20: =IF($A20="","",INDEX('Data Input'!$L$6:$L$143,MATCH($A20,'Data Input'!$S$6:$S$143,0))) -> 5.021131 | E20: =IF($A20="","",IF(D20>5,"Severe",IF(D20>3,"Moderate","Minor"))) -> Severe | F20: =IF($A20="","",INDEX('Data Input'!$F$6:$F$143,MATCH($A20,'Data Input'!$S$6:$S$143,0))) -> 66 | G20: =IF($A20="","",INDEX('Data Input'!$H$6:$H$143,MATCH($A20,'Data Input'!$S$6:$S$143,0))) -> 10 | H20: =IF($A20="","",INDEX('Data Input'!$I$6:$I$143,MATCH($A20,'Data Input'!$S$6:$S$143,0))) -> 0.15151515 | I20: =IF($A20="","",INDEX('Data Input'!$M$6:$M$143,MATCH($A20,'Data Input'!$S$6:$S$143,0))) -> 551.40984 | J20: =IF($A20="","",IFERROR(IF(INDEX('Data Input'!$Q$6:$Q$143,MATCH($A20,'Data Input'!$S$6:$S$143,0))="","",INDEX('Data Input'!$Q$6:$Q$143,MATCH($A20,'Data Input'!$S$6:$S$143,0))),"")) | K20: =IF($A20="","",IFERROR(IF(INDEX('Data Input'!$R$6:$R$143,MATCH($A20,'Data Input'!$S$6:$S$143,0))="","",INDEX('Data Input'!$R$6:$R$143,MATCH($A20,'Data Input'!$S$6:$S$143,0))),""))
A21: =IF(16<=$B$3,16,"") -> 16 | B21: =IF($A21="","",INDEX('Data Input'!$C$6:$C$143,MATCH($A21,'Data Input'!$S$6:$S$143,0))) -> Monday | C21: =IF($A21="","",INDEX('Data Input'!$D$6:$D$143,MATCH($A21,'Data Input'!$S$6:$S$143,0))) -> 0.8125 | D21: =IF($A21="","",INDEX('Data Input'!$L$6:$L$143,MATCH($A21,'Data Input'!$S$6:$S$143,0))) -> 6.25 | E21: =IF($A21="","",IF(D21>5,"Severe",IF(D21>3,"Moderate","Minor"))) -> Severe | F21: =IF($A21="","",INDEX('Data Input'!$F$6:$F$143,MATCH($A21,'Data Input'!$S$6:$S$143,0))) -> 4 | G21: =IF($A21="","",INDEX('Data Input'!$H$6:$H$143,MATCH($A21,'Data Input'!$S$6:$S$143,0))) -> 0 | H21: =IF($A21="","",INDEX('Data Input'!$I$6:$I$143,MATCH($A21,'Data Input'!$S$6:$S$143,0))) -> 0 | I21: =IF($A21="","",INDEX('Data Input'!$M$6:$M$143,MATCH($A21,'Data Input'!$S$6:$S$143,0))) -> 354.8 | J21: =IF($A21="","",IFERROR(IF(INDEX('Data Input'!$Q$6:$Q$143,MATCH($A21,'Data Input'!$S$6:$S$143,0))="","",INDEX('Data Input'!$Q$6:$Q$143,MATCH($A21,'Data Input'!$S$6:$S$143,0))),"")) | K21: =IF($A21="","",IFERROR(IF(INDEX('Data Input'!$R$6:$R$143,MATCH($A21,'Data Input'!$S$6:$S$143,0))="","",INDEX('Data Input'!$R$6:$R$143,MATCH($A21,'Data Input'!$S$6:$S$143,0))),""))
A22: =IF(17<=$B$3,17,"") -> 17 | B22: =IF($A22="","",INDEX('Data Input'!$C$6:$C$143,MATCH($A22,'Data Input'!$S$6:$S$143,0))) -> Tuesday | C22: =IF($A22="","",INDEX('Data Input'!$D$6:$D$143,MATCH($A22,'Data Input'!$S$6:$S$143,0))) -> 0.60416667 | D22: =IF($A22="","",INDEX('Data Input'!$L$6:$L$143,MATCH($A22,'Data Input'!$S$6:$S$143,0))) -> 2.3870766 | E22: =IF($A22="","",IF(D22>5,"Severe",IF(D22>3,"Moderate","Minor"))) -> Minor | F22: =IF($A22="","",INDEX('Data Input'!$F$6:$F$143,MATCH($A22,'Data Input'!$S$6:$S$143,0))) -> 206 | G22: =IF($A22="","",INDEX('Data Input'!$H$6:$H$143,MATCH($A22,'Data Input'!$S$6:$S$143,0))) -> 19 | H22: =IF($A22="","",INDEX('Data Input'!$I$6:$I$143,MATCH($A22,'Data Input'!$S$6:$S$143,0))) -> 0.09223301 | I22: =IF($A22="","",INDEX('Data Input'!$M$6:$M$143,MATCH($A22,'Data Input'!$S$6:$S$143,0))) -> 453.30052 | J22: =IF($A22="","",IFERROR(IF(INDEX('Data Input'!$Q$6:$Q$143,MATCH($A22,'Data Input'!$S$6:$S$143,0))="","",INDEX('Data Input'!$Q$6:$Q$143,MATCH($A22,'Data Input'!$S$6:$S$143,0))),"")) | K22: =IF($A22="","",IFERROR(IF(INDEX('Data Input'!$R$6:$R$143,MATCH($A22,'Data Input'!$S$6:$S$143,0))="","",INDEX('Data Input'!$R$6:$R$143,MATCH($A22,'Data Input'!$S$6:$S$143,0))),""))
A23: =IF(18<=$B$3,18,"") -> 18 | B23: =IF($A23="","",INDEX('Data Input'!$C$6:$C$143,MATCH($A23,'Data Input'!$S$6:$S$143,0))) -> Wednesday | C23: =IF($A23="","",INDEX('Data Input'!$D$6:$D$143,MATCH($A23,'Data Input'!$S$6:$S$143,0))) -> 0.41666667 | D23: =IF($A23="","",INDEX('Data Input'!$L$6:$L$143,MATCH($A23,'Data Input'!$S$6:$S$143,0))) -> 3.2541894 | E23: =IF($A23="","",IF(D23>5,"Severe",IF(D23>3,"Moderate","Minor"))) -> Moderate | F23: =IF($A23="","",INDEX('Data Input'!$F$6:$F$143,MATCH($A23,'Data Input'!$S$6:$S$143,0))) -> 221 | G23: =IF($A23="","",INDEX('Data Input'!$H$6:$H$143,MATCH($A23,'Data Input'!$S$6:$S$143,0))) -> 38 | H23: =IF($A23="","",INDEX('Data Input'!$I$6:$I$143,MATCH($A23,'Data Input'!$S$6:$S$143,0))) -> 0.1719457 | I23: =IF($A23="","",INDEX('Data Input'!$M$6:$M$143,MATCH($A23,'Data Input'!$S$6:$S$143,0))) -> 402.12432 | J23: =IF($A23="","",IFERROR(IF(INDEX('Data Input'!$Q$6:$Q$143,MATCH($A23,'Data Input'!$S$6:$S$143,0))="","",INDEX('Data Input'!$Q$6:$Q$143,MATCH($A23,'Data Input'!$S$6:$S$143,0))),"")) | K23: =IF($A23="","",IFERROR(IF(INDEX('Data Input'!$R$6:$R$143,MATCH($A23,'Data Input'!$S$6:$S$143,0))="","",INDEX('Data Input'!$R$6:$R$143,MATCH($A23,'Data Input'!$S$6:$S$143,0))),""))
A24: =IF(19<=$B$3,19,"") -> 19 | B24: =IF($A24="","",INDEX('Data Input'!$C$6:$C$143,MATCH($A24,'Data Input'!$S$6:$S$143,0))) -> Wednesday | C24: =IF($A24="","",INDEX('Data Input'!$D$6:$D$143,MATCH($A24,'Data Input'!$S$6:$S$143,0))) -> 0.4375 | D24: =IF($A24="","",INDEX('Data Input'!$L$6:$L$143,MATCH($A24,'Data Input'!$S$6:$S$143,0))) -> 3.6851371 | E24: =IF($A24="","",IF(D24>5,"Severe",IF(D24>3,"Moderate","Minor"))) -> Moderate | F24: =IF($A24="","",INDEX('Data Input'!$F$6:$F$143,MATCH($A24,'Data Input'!$S$6:$S$143,0))) -> 259 | G24: =IF($A24="","",INDEX('Data Input'!$H$6:$H$143,MATCH($A24,'Data Input'!$S$6:$S$143,0))) -> 28 | H24: =IF($A24="","",INDEX('Data Input'!$I$6:$I$143,MATCH($A24,'Data Input'!$S$6:$S$143,0))) -> 0.10810811 | I24: =IF($A24="","",INDEX('Data Input'!$M$6:$M$143,MATCH($A24,'Data Input'!$S$6:$S$143,0))) -> 454.63404 | J24: =IF($A24="","",IFERROR(IF(INDEX('Data Input'!$Q$6:$Q$143,MATCH($A24,'Data Input'!$S$6:$S$143,0))="","",INDEX('Data Input'!$Q$6:$Q$143,MATCH($A24,'Data Input'!$S$6:$S$143,0))),"")) | K24: =IF($A24="","",IFERROR(IF(INDEX('Data Input'!$R$6:$R$143,MATCH($A24,'Data Input'!$S$6:$S$143,0))="","",INDEX('Data Input'!$R$6:$R$143,MATCH($A24,'Data Input'!$S$6:$S$143,0))),""))
A25: =IF(20<=$B$3,20,"") -> 20 | B25: =IF($A25="","",INDEX('Data Input'!$C$6:$C$143,MATCH($A25,'Data Input'!$S$6:$S$143,0))) -> Wednesday | C25: =IF($A25="","",INDEX('Data Input'!$D$6:$D$143,MATCH($A25,'Data Input'!$S$6:$S$143,0))) -> 0.45833333 | D25: =IF($A25="","",INDEX('Data Input'!$L$6:$L$143,MATCH($A25,'Data Input'!$S$6:$S$143,0))) -> 2.4049059 | E25: =IF($A25="","",IF(D25>5,"Severe",IF(D25>3,"Moderate","Minor"))) -> Minor | F25: =IF($A25="","",INDEX('Data Input'!$F$6:$F$143,MATCH($A25,'Data Input'!$S$6:$S$143,0))) -> 271 | G25: =IF($A25="","",INDEX('Data Input'!$H$6:$H$143,MATCH($A25,'Data Input'!$S$6:$S$143,0))) -> 23 | H25: =IF($A25="","",INDEX('Data Input'!$I$6:$I$143,MATCH($A25,'Data Input'!$S$6:$S$143,0))) -> 0.084870849 | I25: =IF($A25="","",INDEX('Data Input'!$M$6:$M$143,MATCH($A25,'Data Input'!$S$6:$S$143,0))) -> 455.98016 | J25: =IF($A25="","",IFERROR(IF(INDEX('Data Input'!$Q$6:$Q$143,MATCH($A25,'Data Input'!$S$6:$S$143,0))="","",INDEX('Data Input'!$Q$6:$Q$143,MATCH($A25,'Data Input'!$S$6:$S$143,0))),"")) | K25: =IF($A25="","",IFERROR(IF(INDEX('Data Input'!$R$6:$R$143,MATCH($A25,'Data Input'!$S$6:$S$143,0))="","",INDEX('Data Input'!$R$6:$R$143,MATCH($A25,'Data Input'!$S$6:$S$143,0))),""))
A26: =IF(21<=$B$3,21,"") -> 21 | B26: =IF($A26="","",INDEX('Data Input'!$C$6:$C$143,MATCH($A26,'Data Input'!$S$6:$S$143,0))) -> Wednesday | C26: =IF($A26="","",INDEX('Data Input'!$D$6:$D$143,MATCH($A26,'Data Input'!$S$6:$S$143,0))) -> 0.5 | D26: =IF($A26="","",INDEX('Data Input'!$L$6:$L$143,MATCH($A26,'Data Input'!$S$6:$S$143,0))) -> 3.2457989 | E26: =IF($A26="","",IF(D26>5,"Severe",IF(D26>3,"Moderate","Minor"))) -> Moderate | F26: =IF($A26="","",INDEX('Data Input'!$F$6:$F$143,MATCH($A26,'Data Input'!$S$6:$S$143,0))) -> 276 | G26: =IF($A26="","",INDEX('Data Input'!$H$6:$H$143,MATCH($A26,'Data Input'!$S$6:$S$143,0))) -> 34 | H26: =IF($A26="","",INDEX('Data Input'!$I$6:$I$143,MATCH($A26,'Data Input'!$S$6:$S$143,0))) -> 0.12318841 | I26: =IF($A26="","",INDEX('Data Input'!$M$6:$M$143,MATCH($A26,'Data Input'!$S$6:$S$143,0))) -> 444.76707 | J26: =IF($A26="","",IFERROR(IF(INDEX('Data Input'!$Q$6:$Q$143,MATCH($A26,'Data Input'!$S$6:$S$143,0))="","",INDEX('Data Input'!$Q$6:$Q$143,MATCH($A26,'Data Input'!$S$6:$S$143,0))),"")) | K26: =IF($A26="","",IFERROR(IF(INDEX('Data Input'!$R$6:$R$143,MATCH($A26,'Data Input'!$S$6:$S$143,0))="","",INDEX('Data Input'!$R$6:$R$143,MATCH($A26,'Data Input'!$S$6:$S$143,0))),""))
A27: =IF(22<=$B$3,22,"") -> 22 | B27: =IF($A27="","",INDEX('Data Input'!$C$6:$C$143,MATCH($A27,'Data Input'!$S$6:$S$143,0))) -> Wednesday | C27: =IF($A27="","",INDEX('Data Input'!$D$6:$D$143,MATCH($A27,'Data Input'!$S$6:$S$143,0))) -> 0.52083333 | D27: =IF($A27="","",INDEX('Data Input'!$L$6:$L$143,MATCH($A27,'Data Input'!$S$6:$S$143,0))) -> 4.362963 | E27: =IF($A27="","",IF(D27>5,"Severe",IF(D27>3,"Moderate","Minor"))) -> Moderate | F27: =IF($A27="","",INDEX('Data Input'!$F$6:$F$143,MATCH($A27,'Data Input'!$S$6:$S$143,0))) -> 268 | G27: =IF($A27="","",INDEX('Data Input'!$H$6:$H$143,MATCH($A27,'Data Input'!$S$6:$S$143,0))) -> 61 | H27: =IF($A27="","",INDEX('Data Input'!$I$6:$I$143,MATCH($A27,'Data Input'!$S$6:$S$143,0))) -> 0.22761194 | I27: =IF($A27="","",INDEX('Data Input'!$M$6:$M$143,MATCH($A27,'Data Input'!$S$6:$S$143,0))) -> 436.46789 | J27: =IF($A27="","",IFERROR(IF(INDEX('Data Input'!$Q$6:$Q$143,MATCH($A27,'Data Input'!$S$6:$S$143,0))="","",INDEX('Data Input'!$Q$6:$Q$143,MATCH($A27,'Data Input'!$S$6:$S$143,0))),"")) | K27: =IF($A27="","",IFERROR(IF(INDEX('Data Input'!$R$6:$R$143,MATCH($A27,'Data Input'!$S$6:$S$143,0))="","",INDEX('Data Input'!$R$6:$R$143,MATCH($A27,'Data Input'!$S$6:$S$143,0))),""))
A28: =IF(23<=$B$3,23,"") -> 23 | B28: =IF($A28="","",INDEX('Data Input'!$C$6:$C$143,MATCH($A28,'Data Input'!$S$6:$S$143,0))) -> Wednesday | C28: =IF($A28="","",INDEX('Data Input'!$D$6:$D$143,MATCH($A28,'Data Input'!$S$6:$S$143,0))) -> 0.54166667 | D28: =IF($A28="","",INDEX('Data Input'!$L$6:$L$143,MATCH($A28,'Data Input'!$S$6:$S$143,0))) -> 4.4589094 | E28: =IF($A28="","",IF(D28>5,"Severe",IF(D28>3,"Moderate","Minor"))) -> Moderate | F28: =IF($A28="","",INDEX('Data Input'!$F$6:$F$143,MATCH($A28,'Data Input'!$S$6:$S$143,0))) -> 257 | G28: =IF($A28="","",INDEX('Data Input'!$H$6:$H$143,MATCH($A28,'Data Input'!$S$6:$S$143,0))) -> 40 | H28: =IF($A28="","",INDEX('Data Input'!$I$6:$I$143,MATCH($A28,'Data Input'!$S$6:$S$143,0))) -> 0.15564202 | I28: =IF($A28="","",INDEX('Data Input'!$M$6:$M$143,MATCH($A28,'Data Input'!$S$6:$S$143,0))) -> 407.85202 | J28: =IF($A28="","",IFERROR(IF(INDEX('Data Input'!$Q$6:$Q$143,MATCH($A28,'Data Input'!$S$6:$S$143,0))="","",INDEX('Data Input'!$Q$6:$Q$143,MATCH($A28,'Data Input'!$S$6:$S$143,0))),"")) | K28: =IF($A28="","",IFERROR(IF(INDEX('Data Input'!$R$6:$R$143,MATCH($A28,'Data Input'!$S$6:$S$143,0))="","",INDEX('Data Input'!$R$6:$R$143,MATCH($A28,'Data Input'!$S$6:$S$143,0))),""))
A29: =IF(24<=$B$3,24,"") -> 24 | B29: =IF($A29="","",INDEX('Data Input'!$C$6:$C$143,MATCH($A29,'Data Input'!$S$6:$S$143,0))) -> Wednesday | C29: =IF($A29="","",INDEX('Data Input'!$D$6:$D$143,MATCH($A29,'Data Input'!$S$6:$S$143,0))) -> 0.5625 | D29: =IF($A29="","",INDEX('Data Input'!$L$6:$L$143,MATCH($A29,'Data Input'!$S$6:$S$143,0))) -> 4.0043115 | E29: =IF($A29="","",IF(D29>5,"Severe",IF(D29>3,"Moderate","Minor"))) -> Moderate | F29: =IF($A29="","",INDEX('Data Input'!$F$6:$F$143,MATCH($A29,'Data Input'!$S$6:$S$143,0))) -> 302 | G29: =IF($A29="","",INDEX('Data Input'!$H$6:$H$143,MATCH($A29,'Data Input'!$S$6:$S$143,0))) -> 43 | H29: =IF($A29="","",INDEX('Data Input'!$I$6:$I$143,MATCH($A29,'Data Input'!$S$6:$S$143,0))) -> 0.14238411 | I29: =IF($A29="","",INDEX('Data Input'!$M$6:$M$143,MATCH($A29,'Data Input'!$S$6:$S$143,0))) -> 434.38202 | J29: =IF($A29="","",IFERROR(IF(INDEX('Data Input'!$Q$6:$Q$143,MATCH($A29,'Data Input'!$S$6:$S$143,0))="","",INDEX('Data Input'!$Q$6:$Q$143,MATCH($A29,'Data Input'!$S$6:$S$143,0))),"")) | K29: =IF($A29="","",IFERROR(IF(INDEX('Data Input'!$R$6:$R$143,MATCH($A29,'Data Input'!$S$6:$S$143,0))="","",INDEX('Data Input'!$R$6:$R$143,MATCH($A29,'Data Input'!$S$6:$S$143,0))),""))
A30: =IF(25<=$B$3,25,"") -> 25 | B30: =IF($A30="","",INDEX('Data Input'!$C$6:$C$143,MATCH($A30,'Data Input'!$S$6:$S$143,0))) -> Wednesday | C30: =IF($A30="","",INDEX('Data Input'!$D$6:$D$143,MATCH($A30,'Data Input'!$S$6:$S$143,0))) -> 0.58333333 | D30: =IF($A30="","",INDEX('Data Input'!$L$6:$L$143,MATCH($A30,'Data Input'!$S$6:$S$143,0))) -> 4.4016355 | E30: =IF($A30="","",IF(D30>5,"Severe",IF(D30>3,"Moderate","Minor"))) -> Moderate | F30: =IF($A30="","",INDEX('Data Input'!$F$6:$F$143,MATCH($A30,'Data Input'!$S$6:$S$143,0))) -> 251 | G30: =IF($A30="","",INDEX('Data Input'!$H$6:$H$143,MATCH($A30,'Data Input'!$S$6:$S$143,0))) -> 37 | H30: =IF($A30="","",INDEX('Data Input'!$I$6:$I$143,MATCH($A30,'Data Input'!$S$6:$S$143,0))) -> 0.14741036 | I30: =IF($A30="","",INDEX('Data Input'!$M$6:$M$143,MATCH($A30,'Data Input'!$S$6:$S$143,0))) -> 416.52018 | J30: =IF($A30="","",IFERROR(IF(INDEX('Data Input'!$Q$6:$Q$143,MATCH($A30,'Data Input'!$S$6:$S$143,0))="","",INDEX('Data Input'!$Q$6:$Q$143,MATCH($A30,'Data Input'!$S$6:$S$143,0))),"")) | K30: =IF($A30="","",IFERROR(IF(INDEX('Data Input'!$R$6:$R$143,MATCH($A30,'Data Input'!$S$6:$S$143,0))="","",INDEX('Data Input'!$R$6:$R$143,MATCH($A30,'Data Input'!$S$6:$S$143,0))),""))
A31: =IF(26<=$B$3,26,"") -> 26 | B31: =IF($A31="","",INDEX('Data Input'!$C$6:$C$143,MATCH($A31,'Data Input'!$S$6:$S$143,0))) -> Wednesday | C31: =IF($A31="","",INDEX('Data Input'!$D$6:$D$143,MATCH($A31,'Data Input'!$S$6:$S$143,0))) -> 0.60416667 | D31: =IF($A31="","",INDEX('Data Input'!$L$6:$L$143,MATCH($A31,'Data Input'!$S$6:$S$143,0))) -> 5.9863732 | E31: =IF($A31="","",IF(D31>5,"Severe",IF(D31>3,"Moderate","Minor"))) -> Severe | F31: =IF($A31="","",INDEX('Data Input'!$F$6:$F$143,MATCH($A31,'Data Input'!$S$6:$S$143,0))) -> 240 | G31: =IF($A31="","",INDEX('Data Input'!$H$6:$H$143,MATCH($A31,'Data Input'!$S$6:$S$143,0))) -> 81 | H31: =IF($A31="","",INDEX('Data Input'!$I$6:$I$143,MATCH($A31,'Data Input'!$S$6:$S$143,0))) -> 0.3375 | I31: =IF($A31="","",INDEX('Data Input'!$M$6:$M$143,MATCH($A31,'Data Input'!$S$6:$S$143,0))) -> 463.56024 | J31: =IF($A31="","",IFERROR(IF(INDEX('Data Input'!$Q$6:$Q$143,MATCH($A31,'Data Input'!$S$6:$S$143,0))="","",INDEX('Data Input'!$Q$6:$Q$143,MATCH($A31,'Data Input'!$S$6:$S$143,0))),"")) | K31: =IF($A31="","",IFERROR(IF(INDEX('Data Input'!$R$6:$R$143,MATCH($A31,'Data Input'!$S$6:$S$143,0))="","",INDEX('Data Input'!$R$6:$R$143,MATCH($A31,'Data Input'!$S$6:$S$143,0))),""))
A32: =IF(27<=$B$3,27,"") -> 27 | B32: =IF($A32="","",INDEX('Data Input'!$C$6:$C$143,MATCH($A32,'Data Input'!$S$6:$S$143,0))) -> Wednesday | C32: =IF($A32="","",INDEX('Data Input'!$D$6:$D$143,MATCH($A32,'Data Input'!$S$6:$S$143,0))) -> 0.625 | D32: =IF($A32="","",INDEX('Data Input'!$L$6:$L$143,MATCH($A32,'Data Input'!$S$6:$S$143,0))) -> 5.9647196 | E32: =IF($A32="","",IF(D32>5,"Severe",IF(D32>3,"Moderate","Minor"))) -> Severe | F32: =IF($A32="","",INDEX('Data Input'!$F$6:$F$143,MATCH($A32,'Data Input'!$S$6:$S$143,0))) -> 264 | G32: =IF($A32="","",INDEX('Data Input'!$H$6:$H$143,MATCH($A32,'Data Input'!$S$6:$S$143,0))) -> 50 | H32: =IF($A32="","",INDEX('Data Input'!$I$6:$I$143,MATCH($A32,'Data Input'!$S$6:$S$143,0))) -> 0.18939394 | I32: =IF($A32="","",INDEX('Data Input'!$M$6:$M$143,MATCH($A32,'Data Input'!$S$6:$S$143,0))) -> 441.33484 | J32: =IF($A32="","",IFERROR(IF(INDEX('Data Input'!$Q$6:$Q$143,MATCH($A32,'Data Input'!$S$6:$S$143,0))="","",INDEX('Data Input'!$Q$6:$Q$143,MATCH($A32,'Data Input'!$S$6:$S$143,0))),"")) | K32: =IF($A32="","",IFERROR(IF(INDEX('Data Input'!$R$6:$R$143,MATCH($A32,'Data Input'!$S$6:$S$143,0))="","",INDEX('Data Input'!$R$6:$R$143,MATCH($A32,'Data Input'!$S$6:$S$143,0))),""))
A33: =IF(28<=$B$3,28,"") -> 28 | B33: =IF($A33="","",INDEX('Data Input'!$C$6:$C$143,MATCH($A33,'Data Input'!$S$6:$S$143,0))) -> Wednesday | C33: =IF($A33="","",INDEX('Data Input'!$D$6:$D$143,MATCH($A33,'Data Input'!$S$6:$S$143,0))) -> 0.64583333 | D33: =IF($A33="","",INDEX('Data Input'!$L$6:$L$143,MATCH($A33,'Data Input'!$S$6:$S$143,0))) -> 2.6217842 | E33: =IF($A33="","",IF(D33>5,"Severe",IF(D33>3,"Moderate","Minor"))) -> Minor | F33: =IF($A33="","",INDEX('Data Input'!$F$6:$F$143,MATCH($A33,'Data Input'!$S$6:$S$143,0))) -> 261 | G33: =IF($A33="","",INDEX('Data Input'!$H$6:$H$143,MATCH($A33,'Data Input'!$S$6:$S$143,0))) -> 20 | H33: =IF($A33="","",INDEX('Data Input'!$I$6:$I$143,MATCH($A33,'Data Input'!$S$6:$S$143,0))) -> 0.076628352 | I33: =IF($A33="","",INDEX('Data Input'!$M$6:$M$143,MATCH($A33,'Data Input'!$S$6:$S$143,0))) -> 477.28862 | J33: =IF($A33="","",IFERROR(IF(INDEX('Data Input'!$Q$6:$Q$143,MATCH($A33,'Data Input'!$S$6:$S$143,0))="","",INDEX('Data Input'!$Q$6:$Q$143,MATCH($A33,'Data Input'!$S$6:$S$143,0))),"")) | K33: =IF($A33="","",IFERROR(IF(INDEX('Data Input'!$R$6:$R$143,MATCH($A33,'Data Input'!$S$6:$S$143,0))="","",INDEX('Data Input'!$R$6:$R$143,MATCH($A33,'Data Input'!$S$6:$S$143,0))),""))
A34: =IF(29<=$B$3,29,"") -> 29 | B34: =IF($A34="","",INDEX('Data Input'!$C$6:$C$143,MATCH($A34,'Data Input'!$S$6:$S$143,0))) -> Wednesday | C34: =IF($A34="","",INDEX('Data Input'!$D$6:$D$143,MATCH($A34,'Data Input'!$S$6:$S$143,0))) -> 0.70833333 | D34: =IF($A34="","",INDEX('Data Input'!$L$6:$L$143,MATCH($A34,'Data Input'!$S$6:$S$143,0))) -> 2.5352881 | E34: =IF($A34="","",IF(D34>5,"Severe",IF(D34>3,"Moderate","Minor"))) -> Minor | F34: =IF($A34="","",INDEX('Data Input'!$F$6:$F$143,MATCH($A34,'Data Input'!$S$6:$S$143,0))) -> 208 | G34: =IF($A34="","",INDEX('Data Input'!$H$6:$H$143,MATCH($A34,'Data Input'!$S$6:$S$143,0))) -> 46 | H34: =IF($A34="","",INDEX('Data Input'!$I$6:$I$143,MATCH($A34,'Data Input'!$S$6:$S$143,0))) -> 0.22115385 | I34: =IF($A34="","",INDEX('Data Input'!$M$6:$M$143,MATCH($A34,'Data Input'!$S$6:$S$143,0))) -> 467.70115 | J34: =IF($A34="","",IFERROR(IF(INDEX('Data Input'!$Q$6:$Q$143,MATCH($A34,'Data Input'!$S$6:$S$143,0))="","",INDEX('Data Input'!$Q$6:$Q$143,MATCH($A34,'Data Input'!$S$6:$S$143,0))),"")) | K34: =IF($A34="","",IFERROR(IF(INDEX('Data Input'!$R$6:$R$143,MATCH($A34,'Data Input'!$S$6:$S$143,0))="","",INDEX('Data Input'!$R$6:$R$143,MATCH($A34,'Data Input'!$S$6:$S$143,0))),""))
A35: =IF(30<=$B$3,30,"") -> 30 | B35: =IF($A35="","",INDEX('Data Input'!$C$6:$C$143,MATCH($A35,'Data Input'!$S$6:$S$143,0))) -> Wednesday | C35: =IF($A35="","",INDEX('Data Input'!$D$6:$D$143,MATCH($A35,'Data Input'!$S$6:$S$143,0))) -> 0.72916667 | D35: =IF($A35="","",INDEX('Data Input'!$L$6:$L$143,MATCH($A35,'Data Input'!$S$6:$S$143,0))) -> 7.8756637 | E35: =IF($A35="","",IF(D35>5,"Severe",IF(D35>3,"Moderate","Minor"))) -> Severe | F35: =IF($A35="","",INDEX('Data Input'!$F$6:$F$143,MATCH($A35,'Data Input'!$S$6:$S$143,0))) -> 204 | G35: =IF($A35="","",INDEX('Data Input'!$H$6:$H$143,MATCH($A35,'Data Input'!$S$6:$S$143,0))) -> 91 | H35: =IF($A35="","",INDEX('Data Input'!$I$6:$I$143,MATCH($A35,'Data Input'!$S$6:$S$143,0))) -> 0.44607843 | I35: =IF($A35="","",INDEX('Data Input'!$M$6:$M$143,MATCH($A35,'Data Input'!$S$6:$S$143,0))) -> 440.89474 | J35: =IF($A35="","",IFERROR(IF(INDEX('Data Input'!$Q$6:$Q$143,MATCH($A35,'Data Input'!$S$6:$S$143,0))="","",INDEX('Data Input'!$Q$6:$Q$143,MATCH($A35,'Data Input'!$S$6:$S$143,0))),"")) | K35: =IF($A35="","",IFERROR(IF(INDEX('Data Input'!$R$6:$R$143,MATCH($A35,'Data Input'!$S$6:$S$143,0))="","",INDEX('Data Input'!$R$6:$R$143,MATCH($A35,'Data Input'!$S$6:$S$143,0))),""))
A36: =IF(31<=$B$3,31,"") -> 31 | B36: =IF($A36="","",INDEX('Data Input'!$C$6:$C$143,MATCH($A36,'Data Input'!$S$6:$S$143,0))) -> Wednesday | C36: =IF($A36="","",INDEX('Data Input'!$D$6:$D$143,MATCH($A36,'Data Input'!$S$6:$S$143,0))) -> 0.75 | D36: =IF($A36="","",INDEX('Data Input'!$L$6:$L$143,MATCH($A36,'Data Input'!$S$6:$S$143,0))) -> 11.254372 | E36: =IF($A36="","",IF(D36>5,"Severe",IF(D36>3,"Moderate","Minor"))) -> Severe | F36: =IF($A36="","",INDEX('Data Input'!$F$6:$F$143,MATCH($A36,'Data Input'!$S$6:$S$143,0))) -> 205 | G36: =IF($A36="","",INDEX('Data Input'!$H$6:$H$143,MATCH($A36,'Data Input'!$S$6:$S$143,0))) -> 83 | H36: =IF($A36="","",INDEX('Data Input'!$I$6:$I$143,MATCH($A36,'Data Input'!$S$6:$S$143,0))) -> 0.40487805 | I36: =IF($A36="","",INDEX('Data Input'!$M$6:$M$143,MATCH($A36,'Data Input'!$S$6:$S$143,0))) -> 483.22656 | J36: =IF($A36="","",IFERROR(IF(INDEX('Data Input'!$Q$6:$Q$143,MATCH($A36,'Data Input'!$S$6:$S$143,0))="","",INDEX('Data Input'!$Q$6:$Q$143,MATCH($A36,'Data Input'!$S$6:$S$143,0))),"")) | K36: =IF($A36="","",IFERROR(IF(INDEX('Data Input'!$R$6:$R$143,MATCH($A36,'Data Input'!$S$6:$S$143,0))="","",INDEX('Data Input'!$R$6:$R$143,MATCH($A36,'Data Input'!$S$6:$S$143,0))),""))
A37: =IF(32<=$B$3,32,"") -> 32 | B37: =IF($A37="","",INDEX('Data Input'!$C$6:$C$143,MATCH($A37,'Data Input'!$S$6:$S$143,0))) -> Wednesday | C37: =IF($A37="","",INDEX('Data Input'!$D$6:$D$143,MATCH($A37,'Data Input'!$S$6:$S$143,0))) -> 0.77083333 | D37: =IF($A37="","",INDEX('Data Input'!$L$6:$L$143,MATCH($A37,'Data Input'!$S$6:$S$143,0))) -> 8.4553517 | E37: =IF($A37="","",IF(D37>5,"Severe",IF(D37>3,"Moderate","Minor"))) -> Severe | F37: =IF($A37="","",INDEX('Data Input'!$F$6:$F$143,MATCH($A37,'Data Input'!$S$6:$S$143,0))) -> 167 | G37: =IF($A37="","",INDEX('Data Input'!$H$6:$H$143,MATCH($A37,'Data Input'!$S$6:$S$143,0))) -> 58 | H37: =IF($A37="","",INDEX('Data Input'!$I$6:$I$143,MATCH($A37,'Data Input'!$S$6:$S$143,0))) -> 0.34730539 | I37: =IF($A37="","",INDEX('Data Input'!$M$6:$M$143,MATCH($A37,'Data Input'!$S$6:$S$143,0))) -> 470.75221 | J37: =IF($A37="","",IFERROR(IF(INDEX('Data Input'!$Q$6:$Q$143,MATCH($A37,'Data Input'!$S$6:$S$143,0))="","",INDEX('Data Input'!$Q$6:$Q$143,MATCH($A37,'Data Input'!$S$6:$S$143,0))),"")) | K37: =IF($A37="","",IFERROR(IF(INDEX('Data Input'!$R$6:$R$143,MATCH($A37,'Data Input'!$S$6:$S$143,0))="","",INDEX('Data Input'!$R$6:$R$143,MATCH($A37,'Data Input'!$S$6:$S$143,0))),""))
A38: =IF(33<=$B$3,33,"") -> 33 | B38: =IF($A38="","",INDEX('Data Input'!$C$6:$C$143,MATCH($A38,'Data Input'!$S$6:$S$143,0))) -> Wednesday | C38: =IF($A38="","",INDEX('Data Input'!$D$6:$D$143,MATCH($A38,'Data Input'!$S$6:$S$143,0))) -> 0.79166667 | D38: =IF($A38="","",INDEX('Data Input'!$L$6:$L$143,MATCH($A38,'Data Input'!$S$6:$S$143,0))) -> 12.584848 | E38: =IF($A38="","",IF(D38>5,"Severe",IF(D38>3,"Moderate","Minor"))) -> Severe | F38: =IF($A38="","",INDEX('Data Input'!$F$6:$F$143,MATCH($A38,'Data Input'!$S$6:$S$143,0))) -> 51 | G38: =IF($A38="","",INDEX('Data Input'!$H$6:$H$143,MATCH($A38,'Data Input'!$S$6:$S$143,0))) -> 7 | H38: =IF($A38="","",INDEX('Data Input'!$I$6:$I$143,MATCH($A38,'Data Input'!$S$6:$S$143,0))) -> 0.1372549 | I38: =IF($A38="","",INDEX('Data Input'!$M$6:$M$143,MATCH($A38,'Data Input'!$S$6:$S$143,0))) -> 703.97778 | J38: =IF($A38="","",IFERROR(IF(INDEX('Data Input'!$Q$6:$Q$143,MATCH($A38,'Data Input'!$S$6:$S$143,0))="","",INDEX('Data Input'!$Q$6:$Q$143,MATCH($A38,'Data Input'!$S$6:$S$143,0))),"")) | K38: =IF($A38="","",IFERROR(IF(INDEX('Data Input'!$R$6:$R$143,MATCH($A38,'Data Input'!$S$6:$S$143,0))="","",INDEX('Data Input'!$R$6:$R$143,MATCH($A38,'Data Input'!$S$6:$S$143,0))),""))
A39: =IF(34<=$B$3,34,"") -> 34 | B39: =IF($A39="","",INDEX('Data Input'!$C$6:$C$143,MATCH($A39,'Data Input'!$S$6:$S$143,0))) -> Wednesday | C39: =IF($A39="","",INDEX('Data Input'!$D$6:$D$143,MATCH($A39,'Data Input'!$S$6:$S$143,0))) -> 0.8125 | D39: =IF($A39="","",INDEX('Data Input'!$L$6:$L$143,MATCH($A39,'Data Input'!$S$6:$S$143,0))) -> 17.833333 | E39: =IF($A39="","",IF(D39>5,"Severe",IF(D39>3,"Moderate","Minor"))) -> Severe | F39: =IF($A39="","",INDEX('Data Input'!$F$6:$F$143,MATCH($A39,'Data Input'!$S$6:$S$143,0))) -> 2 | G39: =IF($A39="","",INDEX('Data Input'!$H$6:$H$143,MATCH($A39,'Data Input'!$S$6:$S$143,0))) -> 0 | H39: =IF($A39="","",INDEX('Data Input'!$I$6:$I$143,MATCH($A39,'Data Input'!$S$6:$S$143,0))) -> 0 | I39: =IF($A39="","",INDEX('Data Input'!$M$6:$M$143,MATCH($A39,'Data Input'!$S$6:$S$143,0))) -> 581.5 | J39: =IF($A39="","",IFERROR(IF(INDEX('Data Input'!$Q$6:$Q$143,MATCH($A39,'Data Input'!$S$6:$S$143,0))="","",INDEX('Data Input'!$Q$6:$Q$143,MATCH($A39,'Data Input'!$S$6:$S$143,0))),"")) | K39: =IF($A39="","",IFERROR(IF(INDEX('Data Input'!$R$6:$R$143,MATCH($A39,'Data Input'!$S$6:$S$143,0))="","",INDEX('Data Input'!$R$6:$R$143,MATCH($A39,'Data Input'!$S$6:$S$143,0))),""))
A40: =IF(35<=$B$3,35,"") -> 35 | B40: =IF($A40="","",INDEX('Data Input'!$C$6:$C$143,MATCH($A40,'Data Input'!$S$6:$S$143,0))) -> Thursday | C40: =IF($A40="","",INDEX('Data Input'!$D$6:$D$143,MATCH($A40,'Data Input'!$S$6:$S$143,0))) -> 0.35416667 | D40: =IF($A40="","",INDEX('Data Input'!$L$6:$L$143,MATCH($A40,'Data Input'!$S$6:$S$143,0))) -> 2.9717172 | E40: =IF($A40="","",IF(D40>5,"Severe",IF(D40>3,"Moderate","Minor"))) -> Minor | F40: =IF($A40="","",INDEX('Data Input'!$F$6:$F$143,MATCH($A40,'Data Input'!$S$6:$S$143,0))) -> 117 | G40: =IF($A40="","",INDEX('Data Input'!$H$6:$H$143,MATCH($A40,'Data Input'!$S$6:$S$143,0))) -> 18 | H40: =IF($A40="","",INDEX('Data Input'!$I$6:$I$143,MATCH($A40,'Data Input'!$S$6:$S$143,0))) -> 0.15384615 | I40: =IF($A40="","",INDEX('Data Input'!$M$6:$M$143,MATCH($A40,'Data Input'!$S$6:$S$143,0))) -> 462.43 | J40: =IF($A40="","",IFERROR(IF(INDEX('Data Input'!$Q$6:$Q$143,MATCH($A40,'Data Input'!$S$6:$S$143,0))="","",INDEX('Data Input'!$Q$6:$Q$143,MATCH($A40,'Data Input'!$S$6:$S$143,0))),"")) | K40: =IF($A40="","",IFERROR(IF(INDEX('Data Input'!$R$6:$R$143,MATCH($A40,'Data Input'!$S$6:$S$143,0))="","",INDEX('Data Input'!$R$6:$R$143,MATCH($A40,'Data Input'!$S$6:$S$143,0))),""))
A41: =IF(36<=$B$3,36,"") -> 36 | B41: =IF($A41="","",INDEX('Data Input'!$C$6:$C$143,MATCH($A41,'Data Input'!$S$6:$S$143,0))) -> Thursday | C41: =IF($A41="","",INDEX('Data Input'!$D$6:$D$143,MATCH($A41,'Data Input'!$S$6:$S$143,0))) -> 0.375 | D41: =IF($A41="","",INDEX('Data Input'!$L$6:$L$143,MATCH($A41,'Data Input'!$S$6:$S$143,0))) -> 5.9192506 | E41: =IF($A41="","",IF(D41>5,"Severe",IF(D41>3,"Moderate","Minor"))) -> Severe | F41: =IF($A41="","",INDEX('Data Input'!$F$6:$F$143,MATCH($A41,'Data Input'!$S$6:$S$143,0))) -> 174 | G41: =IF($A41="","",INDEX('Data Input'!$H$6:$H$143,MATCH($A41,'Data Input'!$S$6:$S$143,0))) -> 45 | H41: =IF($A41="","",INDEX('Data Input'!$I$6:$I$143,MATCH($A41,'Data Input'!$S$6:$S$143,0))) -> 0.25862069 | I41: =IF($A41="","",INDEX('Data Input'!$M$6:$M$143,MATCH($A41,'Data Input'!$S$6:$S$143,0))) -> 489.53731 | J41: =IF($A41="","",IFERROR(IF(INDEX('Data Input'!$Q$6:$Q$143,MATCH($A41,'Data Input'!$S$6:$S$143,0))="","",INDEX('Data Input'!$Q$6:$Q$143,MATCH($A41,'Data Input'!$S$6:$S$143,0))),"")) | K41: =IF($A41="","",IFERROR(IF(INDEX('Data Input'!$R$6:$R$143,MATCH($A41,'Data Input'!$S$6:$S$143,0))="","",INDEX('Data Input'!$R$6:$R$143,MATCH($A41,'Data Input'!$S$6:$S$143,0))),""))
...

Sheet Weekly Narrative
A1: Weekly Narrative
A2: Sample data is illustrative only. Replace values using the Data Input sheet each week.
A4: Metric | B4: Result | C4: Interpretation
A5: Total interval/time blocks reviewed | B5: =COUNTA('Data Input'!D6:D143) -> 138 | C5: 14 time blocks reviewed in week
A6: Missed 2-min AWT intervals | B6: =COUNTIF('Data Input'!L6:L143,">2") -> 53 | C6: Intervals where AWT minutes exceeded 2.0 target
A7: Days with missed intervals | B7: {=SUM(--(COUNTIFS('Data Input'!C6:C143,{"Monday","Tuesday","Wednesday","Thursday","Friday","Saturday","Sunday"},'Data Input'!L6:L143,">2")>0))} -> 6 | C7: Days with at least one AWT miss
A8: Days abandon >7% | B8: {=SUM(--(((SUMIFS(I27:I32,A27:A32,{"Monday","Tuesday","Wednesday","Thursday","Friday","Saturday","Sunday"})))>7%))} -> 4 | C8: Days where abandon rate exceeded 7%
A9: Worst AWT minutes | B9: =MAX('Data Input'!L6:L143) -> 17.833333 | C9: Highest average wait time in the sample
A10: Total offered calls | B10: =SUM('Data Input'!F6:F143) -> 26213 | C10: Total demand for week
A11: Total abandoned calls | B11: =SUM('Data Input'!H6:H143) -> 2623 | C11: Total callers who abandoned before handling
A12: Weekly abandon rate | B12: =B11/SUM('Data Input'!F6:F143) -> 0.10006485 | C12: Weekly abandon percentage
A13: Forecast variance | B13: =((SUM('Data Input'!F6:F143)-SUM('Data Input'!E6:E143))/SUM('Data Input'!E6:E143)) -> 0.038467633 | C13: Positive = actual offered calls above forecast
A16: Narrative
A17: The 2-minute AWT target was missed in multiple intervals across the week of 08/03/2026 to 08/08/2026. Monday, Wednesday and Thursday saw the most intervals with misses and it was spread across the whole day. The largest drivers were unplanned shrinkage (especially tardies at the beginning of the day), forecast variance and high AHT. Attrition: 3 from CP360 and 1 from HCL Guatemala 1 Houston agent on LOA
A25: Daily Exception Summary
A26: Day | B26: Missed AWT Blocks | C26: Calls Forecast | D26: Calls Offered | E26: Calls Answered | F26: Calls Abandoned >30s | G26: Abandon >30s % | H26: Calls Abandoned | I26: Abandon % | J26: Forecast Variance % | K26: AHT | L26: ASA | M26: Flag | N26: Unplanned Shrinkage % | O26: Dominant Driver(s)
A27: Monday | B27: =COUNTIFS('Data Input'!C:C,A27,'Data Input'!L:L,">2") -> 16 | C27: =SUMIFS(DataInput[Forecast Calls],DataInput[Day],A27) -> 5930 | D27: =SUMIFS(DataInput[Offered Calls],DataInput[Day],A27) -> 6537 | E27: =SUMIFS(DataInput[Handled Calls],DataInput[Day],A27) -> 5840 | F27: =SUMIFS('Data Input'!J:J,'Data Input'!C:C,A27) -> 537 | G27: =IFERROR(F27/D27,0) -> 0.082147774 | H27: =SUMIFS('Data Input'!F:F,'Data Input'!C:C,A27)-SUMIFS('Data Input'!G:G,'Data Input'!C:C,A27) -> 697 | I27: =IFERROR(H27/D27,0) -> 0.10662383 | J27: =(D27-C27)/C27 -> 0.10236088 | K27: {=SUMPRODUCT(IF(DataInput[Day]=A27,DataInput[Handled Calls]*DataInput[AHT Seconds]))/E27} -> 456.52855 | L27: {=SUMPRODUCT(IF(DataInput[Day]=A27,DataInput[Handled Calls]*DataInput[AWT Minutes]))/E27} -> 2.4604338 | M27: =IF(L27>2,IF(I27>7%,"AWT Miss + Abandon >7%","AWT Miss"),IF(I27>7%,"Abandon >7%","OK")) -> AWT Miss + Abandon >7% | N27: 0.070098912 | O27: Forecast variance + 15 LUPs + 5.4 hrs tech + high AHT (averaging over 460 across missed intervals)
A28: Tuesday | B28: =COUNTIFS('Data Input'!C:C,A28,'Data Input'!L:L,">2") -> 1 | C28: =SUMIFS(DataInput[Forecast Calls],DataInput[Day],A28) -> 4805 | D28: =SUMIFS(DataInput[Offered Calls],DataInput[Day],A28) -> 4139 | E28: =SUMIFS(DataInput[Handled Calls],DataInput[Day],A28) -> 4010 | F28: =SUMIFS('Data Input'!J:J,'Data Input'!C:C,A28) -> 42 | G28: =IFERROR(F28/D28,0) -> 0.010147379 | H28: =SUMIFS('Data Input'!F:F,'Data Input'!C:C,A28)-SUMIFS('Data Input'!G:G,'Data Input'!C:C,A28) -> 129 | I28: =IFERROR(H28/D28,0) -> 0.031166949 | J28: =(D28-C28)/C28 -> -0.13860562 | K28: {=SUMPRODUCT(IF(DataInput[Day]=A28,DataInput[Handled Calls]*DataInput[AHT Seconds]))/E28} -> 440.70642 | L28: {=SUMPRODUCT(IF(DataInput[Day]=A28,DataInput[Handled Calls]*DataInput[AWT Minutes]))/E28} -> 0.37795927 | M28: =IF(L28>2,IF(I28>7%,"AWT Miss + Abandon >7%","AWT Miss"),IF(I28>7%,"Abandon >7%","OK")) -> OK | N28: 0.061677419
A29: Wednesday | B29: =COUNTIFS('Data Input'!C:C,A29,'Data Input'!L:L,">2") -> 17 | C29: =SUMIFS(DataInput[Forecast Calls],DataInput[Day],A29) -> 4490 | D29: =SUMIFS(DataInput[Offered Calls],DataInput[Day],A29) -> 4958 | E29: =SUMIFS(DataInput[Handled Calls],DataInput[Day],A29) -> 4169 | F29: =SUMIFS('Data Input'!J:J,'Data Input'!C:C,A29) -> 695 | G29: =IFERROR(F29/D29,0) -> 0.14017749 | H29: =SUMIFS('Data Input'!F:F,'Data Input'!C:C,A29)-SUMIFS('Data Input'!G:G,'Data Input'!C:C,A29) -> 789 | I29: =IFERROR(H29/D29,0) -> 0.15913675 | J29: =(D29-C29)/C29 -> 0.10423163 | K29: {=SUMPRODUCT(IF(DataInput[Day]=A29,DataInput[Handled Calls]*DataInput[AHT Seconds]))/E29} -> 442.15741 | L29: {=SUMPRODUCT(IF(DataInput[Day]=A29,DataInput[Handled Calls]*DataInput[AWT Minutes]))/E29} -> 3.4669825 | M29: =IF(L29>2,IF(I29>7%,"AWT Miss + Abandon >7%","AWT Miss"),IF(I29>7%,"Abandon >7%","OK")) -> AWT Miss + Abandon >7% | N29: 0.075597015 | O29: Interval level CV spike + high AHT (averaging over 470 across missed intervals) + 2000 DNPs
A30: Thursday | B30: =COUNTIFS('Data Input'!C:C,A30,'Data Input'!L:L,">2") -> 11 | C30: =SUMIFS(DataInput[Forecast Calls],DataInput[Day],A30) -> 4033 | D30: =SUMIFS(DataInput[Offered Calls],DataInput[Day],A30) -> 4058 | E30: =SUMIFS(DataInput[Handled Calls],DataInput[Day],A30) -> 3554 | F30: =SUMIFS('Data Input'!J:J,'Data Input'!C:C,A30) -> 425 | G30: =IFERROR(F30/D30,0) -> 0.10473139 | H30: =SUMIFS('Data Input'!F:F,'Data Input'!C:C,A30)-SUMIFS('Data Input'!G:G,'Data Input'!C:C,A30) -> 504 | I30: =IFERROR(H30/D30,0) -> 0.12419911 | J30: =(D30-C30)/C30 -> 0.0061988594 | K30: {=SUMPRODUCT(IF(DataInput[Day]=A30,DataInput[Handled Calls]*DataInput[AHT Seconds]))/E30} -> 438.38031 | L30: {=SUMPRODUCT(IF(DataInput[Day]=A30,DataInput[Handled Calls]*DataInput[AWT Minutes]))/E30} -> 2.7447665 | M30: =IF(L30>2,IF(I30>7%,"AWT Miss + Abandon >7%","AWT Miss"),IF(I30>7%,"Abandon >7%","OK")) -> AWT Miss + Abandon >7% | N30: 0.06593687 | O30: CV spikes in some intervals + high AHT (averaging over 465 across missed intervals) + 9 LUPs
